2025-04-18 21:35:27,011 INFO    MainThread:2894814 [wandb_setup.py:_flush():67] Current SDK version is 0.19.8
2025-04-18 21:35:27,011 INFO    MainThread:2894814 [wandb_setup.py:_flush():67] Configure stats pid to 2894814
2025-04-18 21:35:27,011 INFO    MainThread:2894814 [wandb_setup.py:_flush():67] Loading settings from /mnt/c_disk/navaneeth/.config/wandb/settings
2025-04-18 21:35:27,011 INFO    MainThread:2894814 [wandb_setup.py:_flush():67] Loading settings from /mnt/e_disk/DA24S008/DA6401_Assignment_2/partB/wandb/settings
2025-04-18 21:35:27,011 INFO    MainThread:2894814 [wandb_setup.py:_flush():67] Loading settings from environment variables
2025-04-18 21:35:27,011 INFO    MainThread:2894814 [wandb_init.py:setup_run_log_directory():647] Logging user logs to /mnt/e_disk/DA24S008/DA6401_Assignment_2/partB/wandb/run-20250418_213527-gls450gu/logs/debug.log
2025-04-18 21:35:27,011 INFO    MainThread:2894814 [wandb_init.py:setup_run_log_directory():648] Logging internal logs to /mnt/e_disk/DA24S008/DA6401_Assignment_2/partB/wandb/run-20250418_213527-gls450gu/logs/debug-internal.log
2025-04-18 21:35:27,011 INFO    MainThread:2894814 [wandb_init.py:monkeypatch_ipython():599] configuring jupyter hooks <wandb.sdk.wandb_init._WandbInit object at 0x7f21a2089630>
2025-04-18 21:35:27,011 INFO    MainThread:2894814 [wandb_init.py:init():761] calling init triggers
2025-04-18 21:35:27,011 INFO    MainThread:2894814 [wandb_init.py:init():766] wandb.init called with sweep_config: {}
config: {'_wandb': {}}
2025-04-18 21:35:27,011 INFO    MainThread:2894814 [wandb_init.py:init():784] starting backend
2025-04-18 21:35:27,011 INFO    MainThread:2894814 [wandb_init.py:init():788] sending inform_init request
2025-04-18 21:35:27,013 INFO    MainThread:2894814 [backend.py:_multiprocessing_setup():101] multiprocessing start_methods=fork,spawn,forkserver, using: spawn
2025-04-18 21:35:27,013 INFO    MainThread:2894814 [wandb_init.py:init():798] backend started and connected
2025-04-18 21:35:27,014 INFO    MainThread:2894814 [wandb_run.py:_label_probe_notebook():1204] probe notebook
2025-04-18 21:35:27,015 INFO    MainThread:2894814 [wandb_init.py:init():891] updated telemetry
2025-04-18 21:35:27,020 INFO    MainThread:2894814 [wandb_init.py:init():915] communicating run to backend with 90.0 second timeout
2025-04-18 21:35:27,516 INFO    MainThread:2894814 [wandb_init.py:init():990] starting run threads in backend
2025-04-18 21:35:27,612 INFO    MainThread:2894814 [wandb_run.py:_console_start():2375] atexit reg
2025-04-18 21:35:27,613 INFO    MainThread:2894814 [wandb_run.py:_redirect():2227] redirect: wrap_raw
2025-04-18 21:35:27,613 INFO    MainThread:2894814 [wandb_run.py:_redirect():2292] Wrapping output streams.
2025-04-18 21:35:27,613 INFO    MainThread:2894814 [wandb_run.py:_redirect():2315] Redirects installed.
2025-04-18 21:35:27,614 INFO    MainThread:2894814 [wandb_init.py:init():1032] run started, returning control to user process
2025-04-18 21:35:29,746 WARNING MsgRouterThr:2894814 [router.py:message_loop():63] message_loop has been closed
Traceback (most recent call last):
  File "/mnt/e_disk/da24s008/lib/python3.10/site-packages/wandb/sdk/interface/router_sock.py", line 27, in _read_message
    return self._sock_client.read_server_response(timeout=1)
  File "/mnt/e_disk/da24s008/lib/python3.10/site-packages/wandb/sdk/lib/sock_client.py", line 235, in read_server_response
    data = self._read_packet_bytes(timeout=timeout)
  File "/mnt/e_disk/da24s008/lib/python3.10/site-packages/wandb/sdk/lib/sock_client.py", line 220, in _read_packet_bytes
    raise SockClientClosedError
wandb.sdk.lib.sock_client.SockClientClosedError

The above exception was the direct cause of the following exception:

Traceback (most recent call last):
  File "/mnt/e_disk/da24s008/lib/python3.10/site-packages/wandb/sdk/interface/router.py", line 56, in message_loop
    msg = self._read_message()
  File "/mnt/e_disk/da24s008/lib/python3.10/site-packages/wandb/sdk/interface/router_sock.py", line 29, in _read_message
    raise MessageRouterClosedError from e
wandb.sdk.interface.router.MessageRouterClosedError
2025-04-18 21:35:29,760 INFO    MsgRouterThr:2894814 [mailbox.py:close():129] Closing mailbox, abandoning 1 handles.
2025-04-18 21:35:29,987 INFO    MainThread:2894814 [jupyter.py:save_ipynb():386] not saving jupyter notebook
2025-04-18 21:35:29,987 INFO    MainThread:2894814 [wandb_init.py:_pause_backend():564] pausing backend
